<?xml version="1.0" encoding="utf-8"?>
<!-- This URDF was automatically created by SolidWorks to URDF Exporter! Originally created by Stephen Brawner (brawner@gmail.com) 
     Commit Version: 1.6.0-4-g7f85cfe  Build Version: 1.6.7995.38578
     For more information, please see http://wiki.ros.org/sw_urdf_exporter -->
<robot
  name="BabyCraneAssemYUp">
  <link
    name="base_link">
    <inertial>
      <origin
        xyz="-0.0087973089746222 0.376613163921915 -0.000184451170872863"
        rpy="0 0 0" />
      <mass
        value="4.82498202935699" />
      <inertia
        ixx="0.0964810475250014"
        ixy="0.00628388066708135"
        ixz="5.44588405851482E-05"
        iyy="0.263944674090472"
        iyz="-1.14845410664111E-05"
        izz="0.26392615278879" />
    </inertial>
    <visual>
      <origin
        xyz="0 0 0"
        rpy="0 0 0" />
      <geometry>
        <mesh
          filename="package://BabyCraneAssemYUp/meshes/base_link.STL" />
      </geometry>
      <material
        name="">
        <color
          rgba="0 0 0 0.9" />
      </material>
    </visual>
    <collision>
      <origin
        xyz="0 0 0"
        rpy="0 0 0" />
      <geometry>
        <mesh
          filename="package://BabyCraneAssemYUp/meshes/base_link.STL" />
      </geometry>
    </collision>
  </link>
  <link
    name="prop1_ccw_link">
    <inertial>
      <origin
        xyz="2.12E-07 5.8411E-08 0.013302"
        rpy="0 0 0" />
      <mass
        value="0.17579" />
      <inertia
        ixx="0.00012645"
        ixy="-0.00018834"
        ixz="-6.0311E-10"
        iyy="0.00037868"
        iyz="-1.0334E-09"
        izz="0.00049687" />
    </inertial>
    <visual>
      <origin
        xyz="0 0 0"
        rpy="0 0 0" />
      <geometry>
        <mesh
          filename="package://BabyCraneAssemYUp/meshes/prop1_ccw_link.STL" />
      </geometry>
      <material
        name="">
        <color
          rgba="0.79216 0.81961 0.93333 1" />
      </material>
    </visual>
    <collision>
      <origin
        xyz="0 0 0"
        rpy="0 0 0" />
      <geometry>
        <mesh
          filename="package://BabyCraneAssemYUp/meshes/prop1_ccw_link.STL" />
      </geometry>
    </collision>
  </link>
  <joint
    name="prop1_ccw_joint"
    type="continuous">
    <origin
      xyz="0.22229 -0.43656 0.57073"
      rpy="0 0 -0.070327" />
    <parent
      link="base_link" />
    <child
      link="prop1_ccw_link" />
    <axis
      xyz="0 0 1" />
  </joint>
  <link
    name="prop2_cw_link">
    <inertial>
      <origin
        xyz="1.5725E-07 2.2285E-07 -0.014372"
        rpy="0 0 0" />
      <mass
        value="0.17576" />
      <inertia
        ixx="0.00012643"
        ixy="0.00018829"
        ixz="3.2569E-10"
        iyy="0.00037853"
        iyz="-9.2354E-10"
        izz="0.00049671" />
    </inertial>
    <visual>
      <origin
        xyz="0 0 0"
        rpy="0 0 0" />
      <geometry>
        <mesh
          filename="package://BabyCraneAssemYUp/meshes/prop2_cw_link.STL" />
      </geometry>
      <material
        name="">
        <color
          rgba="0.79216 0.81961 0.93333 1" />
      </material>
    </visual>
    <collision>
      <origin
        xyz="0 0 0"
        rpy="0 0 0" />
      <geometry>
        <mesh
          filename="package://BabyCraneAssemYUp/meshes/prop2_cw_link.STL" />
      </geometry>
    </collision>
  </link>
  <joint
    name="prop2_cw_joint"
    type="continuous">
    <origin
      xyz="0.22229 0.43656 0.56084"
      rpy="3.1416 0 -1.9866" />
    <parent
      link="base_link" />
    <child
      link="prop2_cw_link" />
    <axis
      xyz="0 0 1" />
  </joint>
  <link
    name="prop3_ccw_link">
    <inertial>
      <origin
        xyz="2.1277E-07 6.1938E-08 0.013302"
        rpy="0 0 0" />
      <mass
        value="0.17579" />
      <inertia
        ixx="0.00012644"
        ixy="-0.00018834"
        ixz="-6.1542E-10"
        iyy="0.00037868"
        iyz="-1.0286E-09"
        izz="0.00049687" />
    </inertial>
    <visual>
      <origin
        xyz="0 0 0"
        rpy="0 0 0" />
      <geometry>
        <mesh
          filename="package://BabyCraneAssemYUp/meshes/prop3_ccw_link.STL" />
      </geometry>
      <material
        name="">
        <color
          rgba="0.79216 0.81961 0.93333 1" />
      </material>
    </visual>
    <collision>
      <origin
        xyz="0 0 0"
        rpy="0 0 0" />
      <geometry>
        <mesh
          filename="package://BabyCraneAssemYUp/meshes/prop3_ccw_link.STL" />
      </geometry>
    </collision>
  </link>
  <joint
    name="prop3_ccw_joint"
    type="continuous">
    <origin
      xyz="-0.42268 0.43656 0.57073"
      rpy="0 0 -1.0628" />
    <parent
      link="base_link" />
    <child
      link="prop3_ccw_link" />
    <axis
      xyz="0 0 1" />
  </joint>
  <link
    name="prop4_cw_link">
    <inertial>
      <origin
        xyz="1.544E-07 2.1895E-07 -0.014372"
        rpy="0 0 0" />
      <mass
        value="0.17576" />
      <inertia
        ixx="0.00012643"
        ixy="0.00018829"
        ixz="3.3625E-10"
        iyy="0.00037852"
        iyz="-9.217E-10"
        izz="0.00049671" />
    </inertial>
    <visual>
      <origin
        xyz="0 0 0"
        rpy="0 0 0" />
      <geometry>
        <mesh
          filename="package://BabyCraneAssemYUp/meshes/prop4_cw_link.STL" />
      </geometry>
      <material
        name="">
        <color
          rgba="0.79216 0.81961 0.93333 1" />
      </material>
    </visual>
    <collision>
      <origin
        xyz="0 0 0"
        rpy="0 0 0" />
      <geometry>
        <mesh
          filename="package://BabyCraneAssemYUp/meshes/prop4_cw_link.STL" />
      </geometry>
    </collision>
  </link>
  <joint
    name="prop4_cw_joint"
    type="continuous">
    <origin
      xyz="-0.42268 -0.43656 0.56084"
      rpy="-3.1416 0 -2.9145" />
    <parent
      link="base_link" />
    <child
      link="prop4_cw_link" />
    <axis
      xyz="0 0 1" />
  </joint>
</robot>